Workbook

Sheet Summary
A1: Employee Dashboard on Azure – Cost Estimate Summary
A2: Two estimates for 50 / 200 / 1,000 people. Figures are list price (₹95.5/$) before PwC's discount and update automatically from the 'Resources & Pricing' tab.
B4: Monthly and yearly cost (₹)
B5: Estimate | E5: Up to 50 | F5: Up to 200 | G5: Up to 1,000
B6: SAVE – lean, accept a few manual steps · per month | E6: ='Resources & Pricing'!L57 -> 2060.207 | F6: ='Resources & Pricing'!M57 -> 2068.1856 | G6: ='Resources & Pricing'!N57 -> 2110.738
B7: per year | E7: =E6*12 -> 24722.484 | F7: =F6*12 -> 24818.227 | G7: =G6*12 -> 25328.856
B8: per person per month | E8: =E6/'Resources & Pricing'!F10 -> 41.204141 | F8: =F6/'Resources & Pricing'!G10 -> 10.340928 | G8: =G6/'Resources & Pricing'!H10 -> 2.110738
B9: SAFE – no room for delay · per month | E9: ='Resources & Pricing'!O57 -> 11424.182 | F9: ='Resources & Pricing'!P57 -> 11451.383 | G9: ='Resources & Pricing'!Q57 -> 18707.383
B10: per year | E10: =E9*12 -> 137090.18 | F10: =F9*12 -> 137416.59 | G10: =G9*12 -> 224488.6
B11: per person per month | E11: =E9/'Resources & Pricing'!F10 -> 228.48364 | F11: =F9/'Resources & Pricing'!G10 -> 57.256913 | G11: =G9/'Resources & Pricing'!H10 -> 18.707383
B12: Extra for SAFE · per month | E12: =E9-E6 -> 9363.9749 | F12: =F9-F6 -> 9383.1971 | G12: =G9-G6 -> 16596.645
B13: Extra for SAFE · per year | E13: =E12*12 -> 112367.7 | F13: =F12*12 -> 112598.36 | G13: =G12*12 -> 199159.74
B14: SAFE saving option: a 1-year reservation on the P0v3 server ($469/year per instance vs $0.082/hour) cuts that line by ~35%. Ask IT.
B16: What you get, and what SAVE compromises
B17: Area | C17: SAVE (lean) | D17: SAFE (no room for delay) | E17: Impact of the SAVE compromise
B18: Server | C18: B1: 1 vCPU, 1.75 GB RAM, one instance | D18: P0v3: 4 GB RAM, faster CPU; 2 instances at ≤1,000 + autoscale | E18: If busy or data grows, pages slow until we click 'upgrade' (minutes, +₹1,255/month for B2)
B19: Testing monthly updates | C19: Upload as 'preview', check via admin link, then set live | D19: Staging slot: test on a copy, swap with zero downtime | E19: Small chance a bad file shows briefly; rollback < 5 minutes
B20: Testing new app versions | C20: Tested locally, then deployed | D20: Separate test environment in Azure | E20: Fixes take slightly longer to verify; small deployment risk
B21: Network security | C21: Private endpoint on the app; storage + Key Vault locked with free service endpoints | D21: Private endpoints on app, test app, storage and Key Vault | E21: If InfoSec rejects service endpoints, we add 2 endpoints (+₹1,500/month) – possible delay waiting for that change
B22: Threat detection | C22: Not included | D22: Defender for App Service | E22: If policy mandates it, we turn it on later (setting)
B23: Audit logs | C23: 30 days | D23: 90 days, more detail | E23: Longer retention can be switched on later
B24: Outages | C24: Single server: Azure patching can cause a few minutes' downtime | D24: 2 servers at ≤1,000 (no single point of failure) | E24: Rare short interruptions
B25: Everything users see | C25: Same | D25: Same | E25: None – both run the same app and the same access rules
B27: Your data, and what it means for sizing
B28: • Today: ~6 MB of data for 3 months (excluding photos) → assume up to ~2 MB more each month.
B29: • Keeping 24 months online → ~48 MB of data. Photos (~25 KB × people) are stored separately and load only when on screen.
B30: • Design rule (both estimates): data is stored per month; pages load the last 3 months by default and older months only when picked in the Month filter. Normal MD visit ≈ 1 MB compressed instead of ~7 MB.
B31: • Server memory: ~48 MB of data needs roughly 1 GB in memory → fits B1 (1.75 GB) but with less headroom each year; P0v3 (4 GB) has years of headroom. See 'Risks & Assumptions'.
B32: • Whatever we choose, the 35–40 MB single HTML file goes away: photos and data are no longer inside the page.

Sheet Resources & Pricing
A1: Resources & Pricing – Save vs Safe, for up to 50 / 200 / 1,000 people
A2: Central India · Linux · pay-as-you-go list prices, Azure Retail Prices API (checked Oct 2026) unless marked. Blue = input you can change · yellow = IT to fill · everything else is a formula.
B4: Inputs
B5: INR per USD | F5: 95.5 | G5: Update to PwC billing rate
B6: PwC enterprise discount | F6: 0 | G6: IT to fill in (0% = list price)
B7: Hours per month | F7: 730 | G7: Azure standard
B9: Usage & data assumptions | F9: Up to 50 | G9: Up to 200 | H9: Up to 1,000 | I9: Why it matters
B10: Users | F10: 50 | G10: 200 | H10: 1000 | I10: Sizes the bandwidth, reads and logs
B11: Visits per user per month | F11: 10 | G11: 10 | H11: 10 | I11: Conservative for a monthly dashboard
B12: Average MB downloaded per visit (compressed) | F12: 3 | G12: 3 | H12: 3 | I12: Page ~1 MB (cached after first visit) + own data slice + on-screen photos
B13: Storage reads per visit | F13: 60 | G13: 60 | H13: 60 | I13: Photos as you scroll + data files
B14: Log MB per user per month | F14: 3 | G14: 3 | H14: 3 | I14: Requests + access audit rows
B15: Data size today, excl. photos (MB) | F15: 6 | G15: 6 | H15: 6 | I15: Stated: ~6,000 KB for 3 months of data
B16: Months of data in that size | F16: 3 | G16: 3 | H16: 3 | I16: Stated
B17: Months of history to keep online | F17: 24 | G17: 24 | H17: 24 | I17: Assumption – older months archived (still in storage, not loaded)
B18: Photo size per person (KB) | F18: 25 | G18: 25 | H18: 25 | I18: Stated: ~25 KB each
B19: → Data growth per month (MB) – assumes all of today's size grows | F19: =F15/F16 -> 2 | G19: =G15/G16 -> 2 | H19: =H15/H16 -> 2 | I19: Upper bound; the profile/skills part does not really grow
B20: → Data kept online after 24 months (MB) | F20: =F19*F17 -> 48 | G20: =G19*G17 -> 48 | H20: =H19*H17 -> 48 | I20: What the server holds in memory if it loads everything
B21: → Photos total (MB) | F21: =F10*F18/1024 -> 1.2207031 | G21: =G10*G18/1024 -> 4.8828125 | H21: =H10*H18/1024 -> 24.414062 | I21: Stored once, loaded only when on screen
B22: → MD full history download, compressed (MB) | F22: =F20*0.15 -> 7.2 | G22: =G20*0.15 -> 7.2 | H22: =H20*0.15 -> 7.2 | I22: If an MD loads ALL months at once (~85% compression). Design loads last 3 months by default
B23: → Default MD download – last 3 months, compressed (MB) | F23: =F19*3*0.15 -> 0.9 | G23: =G19*3*0.15 -> 0.9 | H23: =H19*3*0.15 -> 0.9 | I23: What an MD downloads on a normal visit
B24: → Rough server memory needed (MB) | F24: =F20*8*2+300 -> 1068 | G24: =G20*8*2+300 -> 1068 | H24: =H20*8*2+300 -> 1068 | I24: Data × ~8 in memory × 2 workers + ~300 MB app. B1 = 1,750 MB, B2 = 3,500, P0v3 = 4,000
B25: → Data sent / processed (GB/month) | F25: =F10*F11*F12/1024 -> 1.4648438 | G25: =G10*G11*G12/1024 -> 5.859375 | H25: =H10*H11*H12/1024 -> 29.296875 | I25: Free up to 100 GB/month per subscription
B26: → Storage reads (10K ops/month) | F26: =F10*F11*F13/10000 -> 3 | G26: =G10*G11*G13/10000 -> 12 | H26: =H10*H11*H13/10000 -> 60
B27: → Log GB/month | F27: =F10*F14/1024 -> 0.14648438 | G27: =G10*G14/1024 -> 0.5859375 | H27: =H10*H14/1024 -> 2.9296875 | I27: Free up to 5 GB/month
B30: Resource-by-resource pricing (₹ per month after discount) | F30: Quantities (hours, units, GB) →
A31: # | B31: Resource | C31: What it does | D31: Unit price (USD) | E31: Unit | F31: Save ≤50 | G31: Save ≤200 | H31: Save ≤1000 | I31: Safe ≤50 | J31: Safe ≤200 | K31: Safe ≤1000 | L31: Save ₹ ≤50 | M31: Save ₹ ≤200 | N31: Save ₹ ≤1000 | O31: Safe ₹ ≤50 | P31: Safe ₹ ≤200 | Q31: Safe ₹ ≤1000 | R31: Price source / notes | S31: IT discounted ₹/mo (Safe ≤1000)
A32: 1 | B32: App Service Plan – Basic B1 (Linux), production | C32: Server: 1 vCPU, 1.75 GB RAM | D32: 0.018 | E32: hour | F32: =$F$7 -> 730 | G32: =$F$7 -> 730 | H32: =$F$7 -> 730 | I32: 0 | J32: 0 | K32: 0 | L32: =$D32*F32*$F$5*(1-$F$6) -> 1254.87 | M32: =$D32*G32*$F$5*(1-$F$6) -> 1254.87 | N32: =$D32*H32*$F$5*(1-$F$6) -> 1254.87 | O32: =$D32*I32*$F$5*(1-$F$6) -> 0 | P32: =$D32*J32*$F$5*(1-$F$6) -> 0 | Q32: =$D32*K32*$F$5*(1-$F$6) -> 0 | R32: Azure Retail Prices API, Central India ($0.018/hr)
A33: 2 | B33: App Service Plan – Premium P0v3 (Linux), production | C33: Server: 1 vCPU, 4 GB RAM, faster CPU; staging slot + autoscale included | D33: 0.082 | E33: hour × instance | F33: 0 | G33: 0 | H33: 0 | I33: =$F$7 -> 730 | J33: =$F$7 -> 730 | K33: =2*$F$7 -> 1460 | L33: =$D33*F33*$F$5*(1-$F$6) -> 0 | M33: =$D33*G33*$F$5*(1-$F$6) -> 0 | N33: =$D33*H33*$F$5*(1-$F$6) -> 0 | O33: =$D33*I33*$F$5*(1-$F$6) -> 5716.63 | P33: =$D33*J33*$F$5*(1-$F$6) -> 5716.63 | Q33: =$D33*K33*$F$5*(1-$F$6) -> 11433.26 | R33: Azure Retail Prices API, Central India ($0.082/hr). Safe ≤1000 runs 2 instances all the time
A34: 3 | B34: Staging slot | C34: Test each monthly update on a copy, swap live with zero downtime | D34: 0 | E34: included | F34: 0 | G34: 0 | H34: 0 | I34: 1 | J34: 1 | K34: 1 | L34: =$D34*F34*$F$5*(1-$F$6) -> 0 | M34: =$D34*G34*$F$5*(1-$F$6) -> 0 | N34: =$D34*H34*$F$5*(1-$F$6) -> 0 | O34: =$D34*I34*$F$5*(1-$F$6) -> 0 | P34: =$D34*J34*$F$5*(1-$F$6) -> 0 | Q34: =$D34*K34*$F$5*(1-$F$6) -> 0 | R34: Included in Premium; not available on Basic
A35: 4 | B35: Autoscale | C35: Adds an instance automatically at busy times | D35: 0 | E35: included | F35: 0 | G35: 0 | H35: 0 | I35: 1 | J35: 1 | K35: 1 | L35: =$D35*F35*$F$5*(1-$F$6) -> 0 | M35: =$D35*G35*$F$5*(1-$F$6) -> 0 | N35: =$D35*H35*$F$5*(1-$F$6) -> 0 | O35: =$D35*I35*$F$5*(1-$F$6) -> 0 | P35: =$D35*J35*$F$5*(1-$F$6) -> 0 | Q35: =$D35*K35*$F$5*(1-$F$6) -> 0 | R35: Included in Premium; extra instance-hours beyond the qty above are extra
A36: 5 | B36: Test environment – App Service B1 (Linux) | C36: Separate test app so new versions are tested without touching live | D36: 0.018 | E36: hour | F36: 0 | G36: 0 | H36: 0 | I36: =$F$7 -> 730 | J36: =$F$7 -> 730 | K36: =$F$7 -> 730 | L36: =$D36*F36*$F$5*(1-$F$6) -> 0 | M36: =$D36*G36*$F$5*(1-$F$6) -> 0 | N36: =$D36*H36*$F$5*(1-$F$6) -> 0 | O36: =$D36*I36*$F$5*(1-$F$6) -> 1254.87 | P36: =$D36*J36*$F$5*(1-$F$6) -> 1254.87 | Q36: =$D36*K36*$F$5*(1-$F$6) -> 1254.87 | R36: Azure Retail Prices API, Central India ($0.018/hr). Save tests on the live app's 'preview' instead
A37: 6 | B37: Microsoft Defender for App Service | C37: Threat detection on the production app | D37: 0.02 | E37: hour × instance | F37: 0 | G37: 0 | H37: 0 | I37: =$F$7 -> 730 | J37: =$F$7 -> 730 | K37: =2*$F$7 -> 1460 | L37: =$D37*F37*$F$5*(1-$F$6) -> 0 | M37: =$D37*G37*$F$5*(1-$F$6) -> 0 | N37: =$D37*H37*$F$5*(1-$F$6) -> 0 | O37: =$D37*I37*$F$5*(1-$F$6) -> 1394.3 | P37: =$D37*J37*$F$5*(1-$F$6) -> 1394.3 | Q37: =$D37*K37*$F$5*(1-$F$6) -> 2788.6 | R37: Azure Retail Prices API, Central India ($0.02/hr per instance)
A38: 7 | B38: Private endpoint – production Web App | C38: App reachable only from PwC network/VPN | D38: 0.01 | E38: hour | F38: =$F$7 -> 730 | G38: =$F$7 -> 730 | H38: =$F$7 -> 730 | I38: =$F$7 -> 730 | J38: =$F$7 -> 730 | K38: =$F$7 -> 730 | L38: =$D38*F38*$F$5*(1-$F$6) -> 697.15 | M38: =$D38*G38*$F$5*(1-$F$6) -> 697.15 | N38: =$D38*H38*$F$5*(1-$F$6) -> 697.15 | O38: =$D38*I38*$F$5*(1-$F$6) -> 697.15 | P38: =$D38*J38*$F$5*(1-$F$6) -> 697.15 | Q38: =$D38*K38*$F$5*(1-$F$6) -> 697.15 | R38: Microsoft published Private Link rate ($0.01/hr) – NOT returned by the API; IT to confirm
A39: 8 | B39: Private endpoint – test Web App | C39: Test app also private | D39: 0.01 | E39: hour | F39: 0 | G39: 0 | H39: 0 | I39: =$F$7 -> 730 | J39: =$F$7 -> 730 | K39: =$F$7 -> 730 | L39: =$D39*F39*$F$5*(1-$F$6) -> 0 | M39: =$D39*G39*$F$5*(1-$F$6) -> 0 | N39: =$D39*H39*$F$5*(1-$F$6) -> 0 | O39: =$D39*I39*$F$5*(1-$F$6) -> 697.15 | P39: =$D39*J39*$F$5*(1-$F$6) -> 697.15 | Q39: =$D39*K39*$F$5*(1-$F$6) -> 697.15 | R39: As above
A40: 9 | B40: Private endpoint – Storage | C40: Storage has no public address | D40: 0.01 | E40: hour | F40: 0 | G40: 0 | H40: 0 | I40: =$F$7 -> 730 | J40: =$F$7 -> 730 | K40: =$F$7 -> 730 | L40: =$D40*F40*$F$5*(1-$F$6) -> 0 | M40: =$D40*G40*$F$5*(1-$F$6) -> 0 | N40: =$D40*H40*$F$5*(1-$F$6) -> 0 | O40: =$D40*I40*$F$5*(1-$F$6) -> 697.15 | P40: =$D40*J40*$F$5*(1-$F$6) -> 697.15 | Q40: =$D40*K40*$F$5*(1-$F$6) -> 697.15 | R40: As above. Save uses free service endpoints
A41: 10 | B41: Private endpoint – Key Vault | C41: Key Vault has no public address | D41: 0.01 | E41: hour | F41: 0 | G41: 0 | H41: 0 | I41: =$F$7 -> 730 | J41: =$F$7 -> 730 | K41: =$F$7 -> 730 | L41: =$D41*F41*$F$5*(1-$F$6) -> 0 | M41: =$D41*G41*$F$5*(1-$F$6) -> 0 | N41: =$D41*H41*$F$5*(1-$F$6) -> 0 | O41: =$D41*I41*$F$5*(1-$F$6) -> 697.15 | P41: =$D41*J41*$F$5*(1-$F$6) -> 697.15 | Q41: =$D41*K41*$F$5*(1-$F$6) -> 697.15 | R41: As above. Save uses free service endpoints
A42: 11 | B42: Private endpoint – data processed | C42: Traffic through private endpoints | D42: 0.01 | E42: GB | F42: =F25 -> 1.4648438 | G42: =G25 -> 5.859375 | H42: =H25 -> 29.296875 | I42: =F25*1.2 -> 1.7578125 | J42: =G25*1.2 -> 7.03125 | K42: =H25*1.2 -> 35.15625 | L42: =$D42*F42*$F$5*(1-$F$6) -> 1.3989258 | M42: =$D42*G42*$F$5*(1-$F$6) -> 5.5957031 | N42: =$D42*H42*$F$5*(1-$F$6) -> 27.978516 | O42: =$D42*I42*$F$5*(1-$F$6) -> 1.6787109 | P42: =$D42*J42*$F$5*(1-$F$6) -> 6.7148438 | Q42: =$D42*K42*$F$5*(1-$F$6) -> 33.574219 | R42: $0.01/GB published rate; Safe +20% for storage traffic
A43: 12 | B43: Private DNS zones | C43: Resolve private addresses | D43: 0.5 | E43: zone | F43: 1 | G43: 1 | H43: 1 | I43: 3 | J43: 3 | K43: 3 | L43: =$D43*F43*$F$5*(1-$F$6) -> 47.75 | M43: =$D43*G43*$F$5*(1-$F$6) -> 47.75 | N43: =$D43*H43*$F$5*(1-$F$6) -> 47.75 | O43: =$D43*I43*$F$5*(1-$F$6) -> 143.25 | P43: =$D43*J43*$F$5*(1-$F$6) -> 143.25 | Q43: =$D43*K43*$F$5*(1-$F$6) -> 143.25 | R43: Azure Retail Prices API, Central India ($0.50/zone). ₹0 if PwC central DNS is used
A44: 13 | B44: Storage – data stored (Hot LRS) | C44: Monthly data files, photos, access rules + versions | D44: 0.02 | E44: GB/month | F44: 1 | G44: 1 | H44: 1 | I44: 3 | J44: 3 | K44: 3 | L44: =$D44*F44*$F$5*(1-$F$6) -> 1.91 | M44: =$D44*G44*$F$5*(1-$F$6) -> 1.91 | N44: =$D44*H44*$F$5*(1-$F$6) -> 1.91 | O44: =$D44*I44*$F$5*(1-$F$6) -> 5.73 | P44: =$D44*J44*$F$5*(1-$F$6) -> 5.73 | Q44: =$D44*K44*$F$5*(1-$F$6) -> 5.73 | R44: Azure Retail Prices API, Central India ($0.02/GB). Safe keeps more versions + test copy
...

Sheet Risks & Assumptions
A1: Where SAVE may go wrong – assumptions, warning signs, fix and extra cost
A2: SAFE already covers the items marked 'Yes'. Costs are list ₹/month.
A4: # | B4: Assumption in SAVE | C4: What could break it | D4: How we'd notice | E4: Fix | F4: Time to fix | G4: Extra ₹/month | H4: Covered by SAFE?
A5: 1 | B5: Data stays ≲ 50 MB online (24 months, loaded by month) | C5: We keep all history forever, or load all months at once | D5: Memory alert > 80%; slow pages | E5: Archive months older than 24, or move to B2 | F5: Minutes (setting) | G5: 0 / +1,255 | H5: Yes (4 GB RAM)
A6: 2 | B6: Few people at the same moment (a few dozen) | C6: Town hall / appraisal week, everyone opens it | D6: Slow-response alert; App Insights > 3 s | E6: B1 → B2 or P0v3 (one click) | F6: Minutes | G6: +1,255 to +4,460 | H6: Yes
A7: 3 | B7: InfoSec accepts free service endpoints for Storage and Key Vault | C7: Policy: no public address on anything holding HR data | D7: IT's answer to our request | E7: Add 2 private endpoints + DNS (IT network change) | F7: Days (IT queue) | G7: ~+1,500 | H7: Yes
A8: 4 | B8: No extra security tooling is mandated | C8: Policy requires Defender for App Service | D8: IT/InfoSec review | E8: Turn on Defender | F8: Minutes | G8: ~+1,394 per instance | H8: Yes
A9: 5 | B9: Monthly updates tested with a 'preview' step | C9: A bad file goes live before anyone notices | D9: Users report wrong data | E9: Roll back to last month's file | F9: < 5 minutes | G9: 0 | H9: Yes (staging slot)
A10: 6 | B10: New app versions tested locally | C10: A change works locally but not in Azure | D10: Error alert after deploy | E10: Redeploy previous version | F10: < 15 minutes | G10: 0 (or +1,950 for a test env) | H10: Yes (test env)
A11: 7 | B11: One server instance is enough | C11: Azure patches/restarts the single instance at a busy moment | D11: Short outage alert | E11: Accept, or run 2 instances on Premium | F11: Minutes | G11: +4,460 or more | H11: Yes at ≤1,000
A12: 8 | B12: Logs < 5 GB/month, 30-day retention | C12: Audit asks for longer retention | D12: Audit request | E12: Switch on longer retention | F12: Minutes | G12: +100 to +500 | H12: Yes (90 days)
A13: 9 | B13: Within free 100 GB/month bandwidth | C13: Shared subscription already uses the free tier | D13: Monthly bill | E13: None needed | F13: — | G13: +100 to +300 | H13: Same in both
A14: 10 | B14: Private endpoint price = $0.01/hr published rate | C14: PwC rate differs | D14: IT quote | E14: None – price only | F14: — | G14: ± small | H14: Same in both
A15: 11 | B15: PwC phones can reach private endpoints (mobile VPN) | C15: No mobile VPN on PwC phones | D15: Pilot users can't open it on phones outside office | E15: IT picks Conditional Access or an app gateway instead | F15: Days (IT decision) | G15: 0 or saves ~₹750 | H15: Same in both
B17: Not covered by either estimate (new requirements → separate request and budget)
B18: • Users editing data in the app, or a live HR feed → database (Azure SQL ~₹470–1,430/month) + build effort.
B19: • AI chatbot inside the app → Azure OpenAI billed per question + bigger server.
B20: • Disaster recovery in a second region or zone-redundant setup → roughly +₹9,000–15,000/month or double.
B21: • PwC network costs (ExpressRoute/VPN, central DNS, firewall), internal IT chargeback, GST, developer time.

Sheet Roadmap
A1: Roadmap – what happens, who does it, and when (indicative weeks)
A2: Shaded cells = planned weeks. Weeks depend on IT/InfoSec turnaround. Gate = must be true before the next phase starts.
A4: # | B4: Phase | C4: Workstream | D4: Task | E4: Owner | F4: Gate / done when | G4: W1 | H4: W2 | I4: W3 | J4: W4 | K4: W5 | L4: W6 | M4: W7 | N4: W8 | O4: W9 | P4: W10 | Q4: W11 | R4: W12 | S4: W13 | T4: W14 | U4: Status
A5: 1 | B5: 0. Approvals | C5: Approvals | D5: Managers approve SAVE or SAFE estimate | E5: Charan → Sr managers | F5: Written approval | U5: Not started
A6: 2 | B6: 0. Approvals | C6: Approvals | D6: Send IT request + questions (IT email) | E6: Charan → IT | F6: IT quote + policy answers | U6: Not started
A7: 3 | B7: 0. Approvals | C7: Approvals | D7: Start InfoSec / data-privacy sign-off (no home addresses) | E7: Charan → InfoSec | F7: Sign-off received | U7: Not started
A8: 4 | B8: 0. Approvals | C8: Approvals | D8: MDs confirm access levels + Extra Competencies (Access_Rules.xlsx) | E8: Charan → MDs | F8: Access rules approved | U8: Not started
A9: 5 | B9: 1. Build app | C9: Data | D9: Conversion script: master Excel → per-month data files + error report | E9: Our team | F9: 1-click run, 0 errors | U9: Not started
A10: 6 | B10: 1. Build app | C10: Data | D10: Photos: one ~25 KB file per Employee ID; stop embedding in HTML | E10: Our team | F10: Photo count = headcount | U10: Not started
A11: 7 | B11: 1. Build app | C11: App | D11: Split pages: desktop + mobile < 1 MB, load data from API | E11: Our team | F11: No employee data in page files | U11: Not started
A12: 8 | B12: 1. Build app | C12: App | D12: Server API + role filter (L1–L4, exceptions) on every route | E12: Our team | F12: Test user of each level sees exactly the right data | U12: Not started
A13: 9 | B13: 1. Build app | C13: App | D13: Month-on-demand loading (last 3 months default) | E13: Our team | F13: MD default load ≈ 1 MB | U13: Not started
A14: 10 | B14: 2. Azure setup | C14: Azure | D14: Resource group, VNet, storage, Key Vault, App Service (see 'Azure Build Steps') | E14: IT + Our team | F14: Resources created | U14: Not started
A15: 11 | B15: 2. Azure setup | C15: Azure | D15: Private endpoint(s), DNS, PwC sign-in, groups | E15: IT (Network, Entra) | F15: Opens only on PwC network; forces login | U15: Not started
A16: 12 | B16: 2. Azure setup | C16: Azure | D16: Monitoring, alerts, budget, deployment pipeline | E16: Our team | F16: Test alert received; 1-click deploy | U16: Not started
... A20: 16 | B20: Ongoing | C20: Run | D20: Monthly update (see 'Monthly Ops') | E20: Our team | F20: Live within 5 working days of month-end | U20: Not started

Sheet App Build Checklist
A1: What we need to build (dashboard team) – ready before Azure goes live
A2: Python, same as today's build scripts. Both estimates use exactly this build.
A4: # | B4: Component | C4: What it must do | D4: Details / decisions | E4: Done when | F4: Status
A5: 1 | B5: Conversion script | C5: Turn the monthly master Excel into data files the app reads | D5: Outputs: people.json (profile, role, manager email, competency), skills.json, util_YYYY-MM.json (one per month), rates.json, access_rules.json (from Access_Rules.xlsx). Validates: missing/duplicate emails, managers not found, circular reporting lines, row count vs last month | E5: Runs in one click; error report empty | F5: Not started
A6: 2 | B6: Photo pipeline | C6: One photo per person, small | D6: Resize to ~25 KB (WebP or JPEG), file name = Employee ID; list of people without photo | E6: Photo count = headcount | F6: Not started
A7: 3 | B7: Page shells (desktop + mobile) | C7: Same look and tabs as today, no data inside | D7: Remove embedded data/photos from templates; fetch from API; lazy-load photos; Month filter requests extra months on demand; detect mobile vs desktop | E7: Each page < 1 MB; works on phone | F7: Not started
A8: 4 | B8: Server app (API) | C8: Small web app on App Service | D8: Routes: /api/me (who am I + level), /api/people, /api/skills, /api/utilization?months=, /api/rates, /photo/<id>, /api/export (if CSV export kept). Reads files from Blob via managed identity; caches in memory; reloads when a new month is published | E8: All routes respond < 1 s | F8: Not started
A9: 5 | B9: Identity | C9: Know who is signed in | D9: Read the signed-in user's email from App Service authentication header (X-MS-CLIENT-PRINCIPAL); read group membership for AllAccess / RateViewer | E9: Unknown email → 'No access' page | F9: Not started
A10: 6 | B10: Role filter | C10: Send only allowed rows and columns | D10: Level from Role default + User Overrides; scope = self / reporting tree / own + extra competencies / all; field groups G0–G6 from Access_Rules; default-deny for unknown columns; gender as totals only where set | E10: Test matrix passes (next row) | F10: Not started
A11: 7 | B11: Access test matrix | C11: Prove nobody sees too much | D11: At least one test user per level (L1–L4) + an override + an extra-competency Director + an unknown email; check every route incl. photos and export | E11: All checks pass; MD signs off | F11: Not started
A12: 8 | B12: Preview / publish switch (SAVE) or slot swap (SAFE) | C12: Safe monthly go-live | D12: SAVE: app setting ACTIVE_MONTH_SET=preview|live, admin-only preview link. SAFE: deploy data to staging slot, swap | E12: Rollback tested (< 5 min) | F12: Not started
A13: 9 | B13: Logging | C13: Audit and troubleshooting | D13: Log user, time, level, route, records returned (no personal data values) to Application Insights | E13: Logs visible; no data values in logs | F13: Not started
A14: 10 | B14: Deployment pipeline | C14: Same steps every time | D14: GitHub Actions or Azure DevOps (whichever PwC licenses): build → deploy (SAFE: to staging) → health check | E14: 1-click deploy works | F14: Not started
A15: 11 | B15: Runbook | C15: Anyone on the team can do the monthly update | D15: Short document: steps, where files go, how to roll back, who to call | E15: A refresh done by someone other than the developer | F15: Not started

Sheet Azure Build Steps
A1: Building it in Azure – step by step, with exact settings
A2: Do in this order. 'SAFE adds' shows the extra step for the Safe estimate. Owner: IT = PwC IT/Cloud team; Team = dashboard team.
A4: # | B4: Step | C4: Exact settings | D4: SAFE adds | E4: Owner | F4: Check it worked | G4: Status
A5: 1 | B5: Subscription + resource group | C5: Region Central India; name e.g. rg-deals-dashboard-prod; tags: owner, cost centre, data class = HR/Confidential | D5: rg-deals-dashboard-test for the test environment | E5: IT | F5: Team has Contributor on the RG | G5: Not started
A6: 2 | B6: Virtual network | C6: 1 VNet (e.g. /24); subnet A for private endpoints (/27); subnet B for App Service VNet integration (/26, delegated to Microsoft.Web/serverFarms); NSG on both | D6: Room for test app integration subnet (/26) | E6: IT (Network) | F6: VNet + subnets visible | G6: Not started
A7: 3 | B7: Storage account | C7: StorageV2, Standard, LRS, Hot; public blob access OFF; minimum TLS 1.2; containers: data, photos, config; blob versioning + soft delete (14 days); network: allow only subnet B (service endpoint) | D7: Private endpoint for blob in subnet A; public network access OFF | E7: Team (+IT for network) | F7: Anonymous URL returns error | G7: Not started
A8: 4 | B8: Key Vault | C8: Standard; RBAC permission model; soft delete + purge protection; network: allow only subnet B | D8: Private endpoint for vault in subnet A | E8: Team (+IT) | F8: Vault created | G8: Not started
A9: 5 | B9: App Service plan + Web App | C9: Linux; SAVE: plan B1, 1 instance. Runtime Python 3.x; HTTPS only; minimum TLS 1.2; FTP off; Always On ON; compression ON; system-assigned managed identity ON; VNet integration → subnet B | D9: Plan P0v3; staging slot 'staging'; autoscale min 1 / max 2 (≤1,000: min 2); test Web App on its own B1 plan | E9: Team | F9: Default page loads (inside PwC network) | G9: Not started
A10: 6 | B10: Private endpoint for the Web App | C10: Private endpoint in subnet A for the Web App (sites); public network access OFF; DNS zone privatelink.azurewebsites.net linked to VNet or PwC central DNS | D10: Same for the test Web App | E10: IT (Network) | F10: Opens on PwC network/VPN; blocked outside | G10: Not started
A11: 7 | B11: Permissions for the app | C11: Managed identity → 'Storage Blob Data Reader' on the storage account; 'Key Vault Secrets User' on the vault | D11: Same for test app (test data only) | E11: Team | F11: App reads a file with no keys in code | G11: Not started
A12: 8 | B12: PwC sign-in | C12: Entra ID app registration (single tenant); App Service Authentication → Microsoft provider → 'Require authentication'; redirect URI /.auth/login/aad/callback; groups Dashboard.AllAccess and Dashboard.RateViewer; include group claims | D12: Same registration pattern for test app | E12: IT (Entra admin) | F12: Opening the link forces PwC login; groups visible to app | G12: Not started
A13: 9 | B13: Mobile access decision | C13: Based on IT's answer: mobile VPN (keep private endpoint) or Conditional Access requiring MFA + PwC-managed device | D13: — | E13: IT | F13: MD can open it on a PwC phone outside the office | G13: Not started
A14: 10 | B14: Monitoring | C14: Log Analytics workspace (30-day retention); Application Insights (workspace-based) connected to the Web App; diagnostic settings for App Service and storage | D14: Retention 90 days; Defender for App Service ON | E14: Team | F14: Requests visible in App Insights | G14: Not started
A15: 11 | B15: Alerts | C15: Metric alerts: HTTP 5xx > threshold, response time > 3 s, CPU > 80%, memory > 80%; log alert: monthly upload failed; action group → team email | D15: + unusual access pattern alert; availability alerts on staging | E15: Team | F15: Test alert email received | G15: Not started
A16: 12 | B16: Cost guardrail | C16: Cost Management budget = estimate + 25%, alert at 80% and 100% to team + IT | D16: — | E16: Team | F16: Budget visible | G16: Not started
... A19: 15 | B19: Security sign-off | C19: Share this sheet + architecture with IT Security; fix findings | D19: Defender recommendations reviewed | E19: IT Security | F19: Sign-off received | G19: Not started

Sheet Monthly Ops
A1: Every month – within 5 working days of month-end
A2: Same in both estimates except how the new month is tested and published.
A4: # | B4: Step | C4: What to do | D4: SAVE | E4: SAFE | F4: Done when
A5: 1 | B5: Collect extracts | C5: Utilization, skills, bio, joiners/leavers/transfers | D5: Same | E5: Same | F5: All received
A6: 2 | B6: Update master Excel | C6: Add joiners (email + RL Manager Email), remove leavers, update manager changes | D6: Same | E6: Same | F6: Headcount matches HR list
A7: 3 | B7: Update photos | C7: Add joiners' photos, remove leavers' | D7: Same | E7: Same | F7: Photo count = headcount
A8: 4 | B8: Run conversion script | C8: Creates this month's data file; fix anything the error report flags | D8: Same | E8: Same | F8: 0 errors
A9: 5 | B9: Upload | C9: Upload new month file + photos | D9: Upload as 'preview' | E9: Upload to staging slot | F9: File in storage
A10: 6 | B10: Check | C10: Open as test MD, Manager and SA; check counts, new month, photos | D10: Admin preview link | E10: Staging URL | F10: Each level correct
A11: 7 | B11: Publish | C11: Make it live | D11: Switch preview → live | E11: Swap staging → live | F11: Live site shows new month
A12: 8 | B12: Archive | C12: Months older than 24 move to archive folder (not loaded) | D12: Same | E12: Same | F12: Data online ≤ 24 months
A13: 9 | B13: Announce + review | C13: Short note; check errors, usage, access log, cost vs budget | D13: Same | E13: Same | F13: No open issues
A14: 10 | B14: Rollback (if needed) | C14: Return to last month | D14: Switch back to last file | E14: Swap slot back | F14: < 5 minutes
A15: 11 | B15: Access changes (as needed) | C15: New MD/Director → IT updates Entra group; exceptions → Access_Rules.xlsx with approval + expiry | D15: Same | E15: Same | F15: Effective at next sign-in

Sheet IT Questions
A1: Open questions for IT – answers decide the final cost and design
A2: Send with the IT email. Fill the answer column as replies come in.
A4: # | B4: Question for IT | C4: Why it matters | D4: Cost / design impact | E4: IT answer
A5: 1 | B5: What is PwC's discounted price per line (or overall discount %)? | C5: Turns list price into actual cost | D5: Updates every total
A6: 2 | B6: Are service endpoints acceptable for Storage and Key Vault, or are private endpoints mandatory? | C6: Biggest open cost item | D6: +~₹1,500/month if mandatory (already in SAFE)
A7: 3 | B7: Can we use PwC's central private DNS zones? | C7: Avoids creating our own zones | D7: Saves ₹48–143/month
A8: 4 | B8: Do PwC mobiles have VPN/tunnel access to private endpoints? If not, what is the standard for internal apps on phones (Conditional Access / app gateway)? | C8: MDs need it on phones outside office | D8: May replace the private endpoint (saves ~₹750/month) or add none
A9: 5 | B9: Is Defender for App Service (or any other tool) mandatory? | C9: Policy item | D9: +₹1,394/month per instance (in SAFE)
A10: 6 | B10: Is a separate test/dev environment required? | C10: Policy item | D10: +~₹1,950/month (in SAFE)
A11: 7 | B11: Which subscription will this sit in, and is its free 100 GB/month bandwidth already used? | C11: Bandwidth charges | D11: +₹100–300/month at most
A12: 8 | B12: Do we get Contributor on the resource group, and who creates the network pieces? | C12: Who does which step | D12: Timeline
A13: 9 | B13: Which CI/CD tool is licensed (GitHub Actions / Azure DevOps)? | C13: Deployment pipeline | D13: None
A14: 10 | B14: Any naming, tagging, region or data-classification standards for HR data? | C14: Compliance | D14: None
A15: 11 | B15: Discounted price of P0v3 Linux, pay-as-you-go and 1-year reserved? | C15: SAFE estimate and scale-up option | D15: Could cut SAFE server cost ~35%
A16: 12 | B16: Expected lead time for resource creation and InfoSec review? | C16: Roadmap dates | D16: Timeline
